<?xml version="1.0" encoding="utf-8"?>
<!-- This URDF was automatically created by SolidWorks to URDF Exporter! Originally created by Stephen Brawner (brawner@gmail.com) 
     Commit Version: 1.6.0-4-g7f85cfe  Build Version: 1.6.7995.38578
     For more information, please see http://wiki.ros.org/sw_urdf_exporter -->
<robot
  name="krys_urdf2">
  <link
    name="base_link">
    <inertial>
      <origin
        xyz="-0.00027833 -0.00035529 0.28058"
        rpy="0 0 0" />
      <mass
        value="241.11" />
      <inertia
        ixx="11.815"
        ixy="-6.2754E-07"
        ixz="1.9106E-08"
        iyy="11.817"
        iyz="-3.6365E-06"
        izz="3.1907" />
    </inertial>
    <visual>
      <origin
        xyz="0 0 0"
        rpy="0 0 0" />
      <geometry>
        <mesh
          filename="package://krys_urdf2/meshes/base_link.STL" />
      </geometry>
      <material
        name="">
        <color
          rgba="0.65098 0.61961 0.58824 1" />
      </material>
    </visual>
    <collision>
      <origin
        xyz="0 0 0"
        rpy="0 0 0" />
      <geometry>
        <mesh
          filename="package://krys_urdf2/meshes/base_link.STL" />
      </geometry>
    </collision>
  </link>
  <link
    name="linear_act1">
    <inertial>
      <origin
        xyz="0.0014606 0.013461 -0.00098929"
        rpy="0 0 0" />
      <mass
        value="1.5094" />
      <inertia
        ixx="0.0011055"
        ixy="9.2644E-07"
        ixz="-1.8929E-07"
        iyy="0.0012926"
        iyz="-5.1182E-06"
        izz="0.00043431" />
    </inertial>
    <visual>
      <origin
        xyz="0 0 0"
        rpy="0 0 0" />
      <geometry>
        <mesh
          filename="package://krys_urdf2/meshes/linear_act1.STL" />
      </geometry>
      <material
        name="">
        <color
          rgba="0.65098 0.61961 0.58824 1" />
      </material>
    </visual>
    <collision>
      <origin
        xyz="0 0 0"
        rpy="0 0 0" />
      <geometry>
        <mesh
          filename="package://krys_urdf2/meshes/linear_act1.STL" />
      </geometry>
    </collision>
  </link>
  <joint
    name="linear_joint1"
    type="prismatic">
    <origin
      xyz="0.055183 0.047931 1.1839"
      rpy="0 0 -3.1416" />
    <parent
      link="base_link" />
    <child
      link="linear_act1" />
    <axis
      xyz="0 0 1" />
    <limit
      lower="-1"
      upper="1"
      effort="0"
      velocity="0" />
  </joint>
  <link
    name="link4">
    <inertial>
      <origin
        xyz="-0.18768 -0.030083 -0.088212"
        rpy="0 0 0" />
      <mass
        value="3.0252" />
      <inertia
        ixx="0.010732"
        ixy="0.00012434"
        ixz="-0.014821"
        iyy="0.03425"
        iyz="8.2694E-05"
        izz="0.024095" />
    </inertial>
    <visual>
      <origin
        xyz="0 0 0"
        rpy="0 0 0" />
      <geometry>
        <mesh
          filename="package://krys_urdf2/meshes/link4.STL" />
      </geometry>
      <material
        name="">
        <color
          rgba="0.65098 0.61961 0.58824 1" />
      </material>
    </visual>
    <collision>
      <origin
        xyz="0 0 0"
        rpy="0 0 0" />
      <geometry>
        <mesh
          filename="package://krys_urdf2/meshes/link4.STL" />
      </geometry>
    </collision>
  </link>
  <joint
    name="joint4"
    type="revolute">
    <origin
      xyz="0.0475 -0.055712 -0.0205"
      rpy="0 0 3.1416" />
    <parent
      link="linear_act1" />
    <child
      link="link4" />
    <axis
      xyz="0 1 0" />
    <limit
      lower="-3"
      upper="3"
      effort="0"
      velocity="0" />
  </joint>
  <link
    name="link5">
    <inertial>
      <origin
        xyz="-3.042E-14 2.9976E-15 0.15375"
        rpy="0 0 0" />
      <mass
        value="0.47881" />
      <inertia
        ixx="0.0049496"
        ixy="-3.5308E-20"
        ixz="5.6074E-19"
        iyy="0.0049609"
        iyz="-1.7603E-18"
        izz="3.6427E-05" />
    </inertial>
    <visual>
      <origin
        xyz="0 0 0"
        rpy="0 0 0" />
      <geometry>
        <mesh
          filename="package://krys_urdf2/meshes/link5.STL" />
      </geometry>
      <material
        name="">
        <color
          rgba="0.89804 0.91765 0.92941 1" />
      </material>
    </visual>
    <collision>
      <origin
        xyz="0 0 0"
        rpy="0 0 0" />
      <geometry>
        <mesh
          filename="package://krys_urdf2/meshes/link5.STL" />
      </geometry>
    </collision>
  </link>
  <joint
    name="link5_joint"
    type="prismatic">
    <origin
      xyz="-0.44473 -0.023212 -0.25598"
      rpy="0 1.0164 0" />
    <parent
      link="link4" />
    <child
      link="link5" />
    <axis
      xyz="0 0 1" />
    <limit
      lower="-1"
      upper="1"
      effort="0"
      velocity="0" />
  </joint>
  <link
    name="end_effector_link">
    <inertial>
      <origin
        xyz="2.4869E-14 3.6082E-16 -0.0042612"
        rpy="0 0 0" />
      <mass
        value="0.003974" />
      <inertia
        ixx="1.2877E-07"
        ixy="-4.4636E-22"
        ixz="-4.169E-22"
        iyy="4.5237E-07"
        iyz="1.9173E-23"
        izz="4.8735E-07" />
    </inertial>
    <visual>
      <origin
        xyz="0 0 0"
        rpy="0 0 0" />
      <geometry>
        <mesh
          filename="package://krys_urdf2/meshes/end_effector_link.STL" />
      </geometry>
      <material
        name="">
        <color
          rgba="0.49804 0.49804 0.49804 1" />
      </material>
    </visual>
    <collision>
      <origin
        xyz="0 0 0"
        rpy="0 0 0" />
      <geometry>
        <mesh
          filename="package://krys_urdf2/meshes/end_effector_link.STL" />
      </geometry>
    </collision>
  </link>
  <joint
    name="endeffector_joint"
    type="revolute">
    <origin
      xyz="0.00057642 0 -0.1235"
      rpy="-3.1416 0 3.1416" />
    <parent
      link="link5" />
    <child
      link="end_effector_link" />
    <axis
      xyz="-1 0 0" />
    <limit
      lower="-3"
      upper="3"
      effort="0"
      velocity="0" />
  </joint>
  <link
    name="linear_act2">
    <inertial>
      <origin
        xyz="0 0 0"
        rpy="0 0 0" />
      <mass
        value="0" />
      <inertia
        ixx="0"
        ixy="0"
        ixz="0"
        iyy="0"
        iyz="0"
        izz="0" />
    </inertial>
    <visual>
      <origin
        xyz="0 0 0"
        rpy="0 0 0" />
      <geometry>
        <mesh
          filename="package://krys_urdf2/meshes/linear_act2.STL" />
      </geometry>
      <material
        name="">
        <color
          rgba="1 1 1 1" />
      </material>
    </visual>
    <collision>
      <origin
        xyz="0 0 0"
        rpy="0 0 0" />
      <geometry>
        <mesh
          filename="package://krys_urdf2/meshes/linear_act2.STL" />
      </geometry>
    </collision>
  </link>
  <joint
    name="linear_joint2"
    type="prismatic">
    <origin
      xyz="-0.059817 0.017931 0.85103"
      rpy="0 0 0" />
    <parent
      link="base_link" />
    <child
      link="linear_act2" />
    <axis
      xyz="0 0 -1" />
    <limit
      lower="-1"
      upper="1"
      effort="0"
      velocity="0" />
  </joint>
  <link
    name="rod_link">
    <inertial>
      <origin
        xyz="0.069844 -0.010465 -0.035734"
        rpy="0 0 0" />
      <mass
        value="0.13877" />
      <inertia
        ixx="6.415E-05"
        ixy="4.3588E-12"
        ixz="0.00011921"
        iyy="0.00029542"
        iyz="-3.1075E-12"
        izz="0.00023335" />
    </inertial>
    <visual>
      <origin
        xyz="0 0 0"
        rpy="0 0 0" />
      <geometry>
        <mesh
          filename="package://krys_urdf2/meshes/rod_link.STL" />
      </geometry>
      <material
        name="">
        <color
          rgba="0.89804 0.89804 0.89804 1" />
      </material>
    </visual>
    <collision>
      <origin
        xyz="0 0 0"
        rpy="0 0 0" />
      <geometry>
        <mesh
          filename="package://krys_urdf2/meshes/rod_link.STL" />
      </geometry>
    </collision>
  </link>
  <joint
    name="rod_joint"
    type="revolute">
    <origin
      xyz="-0.044 0.027465 -0.012155"
      rpy="3.1416 0 3.1416" />
    <parent
      link="linear_act2" />
    <child
      link="rod_link" />
    <axis
      xyz="0 -1 0" />
    <limit
      lower="-3"
      upper="3"
      effort="0"
      velocity="0" />
  </joint>
  <link
    name="barrel_link">
    <inertial>
      <origin
        xyz="0.032934 -0.0059385 -0.017013"
        rpy="0 0 0" />
      <mass
        value="0.045457" />
      <inertia
        ixx="2.9834E-05"
        ixy="-1.8355E-07"
        ixz="4.9972E-05"
        iyy="0.00012915"
        iyz="9.4816E-08"
        izz="0.00010076" />
    </inertial>
    <visual>
      <origin
        xyz="0 0 0"
        rpy="0 0 0" />
      <geometry>
        <mesh
          filename="package://krys_urdf2/meshes/barrel_link.STL" />
      </geometry>
      <material
        name="">
        <color
          rgba="1 1 1 0.32" />
      </material>
    </visual>
    <collision>
      <origin
        xyz="0 0 0"
        rpy="0 0 0" />
      <geometry>
        <mesh
          filename="package://krys_urdf2/meshes/barrel_link.STL" />
      </geometry>
    </collision>
  </link>
  <joint
    name="barrel_joint"
    type="prismatic">
    <origin
      xyz="0.135973968895168 -0.00446514539888075 -0.0698936287062597"
      rpy="0 0 0" />
    <parent
      link="rod_link" />
    <child
      link="barrel_link" />
    <axis
      xyz="0.888464694121165 0 -0.458944971973966" />
    <limit
      lower="-1"
      upper="1"
      effort="0"
      velocity="0" />
  </joint>
  <link
    name="link3">
    <inertial>
      <origin
        xyz="-1.2141E-05 0.0025004 -5.9644E-05"
        rpy="0 0 0" />
      <mass
        value="0.0025159" />
      <inertia
        ixx="2.8785E-08"
        ixy="-1.7842E-13"
        ixz="2.5002E-12"
        iyy="4.7098E-08"
        iyz="-3.9754E-13"
        izz="2.8793E-08" />
    </inertial>
    <visual>
      <origin
        xyz="0 0 0"
        rpy="0 0 0" />
      <geometry>
        <mesh
          filename="package://krys_urdf2/meshes/link3.STL" />
      </geometry>
      <material
        name="">
        <color
          rgba="0.53725 0.34902 0.33725 1" />
      </material>
    </visual>
    <collision>
      <origin
        xyz="0 0 0"
        rpy="0 0 0" />
      <geometry>
        <mesh
          filename="package://krys_urdf2/meshes/link3.STL" />
      </geometry>
    </collision>
  </link>
  <joint
    name="linkl3_joint"
    type="revolute">
    <origin
      xyz="0.0986332868458225 -0.0114999999999951 -0.050883290902993"
      rpy="0 0 0" />
    <parent
      link="barrel_link" />
    <child
      link="link3" />
    <axis
      xyz="0 -1 0" />
    <limit
      lower="-3"
      upper="3"
      effort="0"
      velocity="0" />
  </joint>
</robot>